# An√°lisis Detallado de Errores en Logs de Producci√≥n (05/08/2025)

A continuaci√≥n se presenta un an√°lisis de los errores cr√≠ticos identificados en los logs del servicio `expert-bot-api` a partir de las 16:30 (hora local, correspondiente a las 14:30 UTC).

---

## 1. Errores en el servicio: `expert-bot-api`

### Error 1.1: Error de C√≥digo en la L√≥gica de Autenticaci√≥n ‚úÖ VERIFICADO ‚úÖ SOLUCIONADO

- **Timestamp (UTC):** 2025-08-05T15:08:01.794289Z (17:08 Hora Local)
- **Endpoint Afectado:** `POST /api/v1/energy/consumption`
- **Mensaje de Error Clave:** `Error en decorador token_required: 'AILearningService' object has no attribute 'process_invoice_upload_patterns'`

**VERIFICACI√ìN DEL C√ìDIGO CONFIRMADA:**

- **Archivo:** `expert_bot_api_COPY/app/energy_routes.py` (l√≠nea 118)
- **M√©todo faltante:** `process_invoice_upload_patterns` no existe en `AILearningService`
- **Clase afectada:** `app/services/ai_learning_service.py` (2400+ l√≠neas, m√©todo deber√≠a estar en l√≠nea ~2405)

**C√ìDIGO VERIFICADO QUE GENERA EL ERROR:**

```python
# L√≠nea 118 en energy_routes.py
ai_learning.process_invoice_upload_patterns(user_id, file.filename, result)
```

**SOLUCI√ìN IMPLEMENTADA Y VERIFICADA:**

- **Archivo:** `expert_bot_api_COPY/app/services/ai_learning_service.py` (l√≠nea 2401)
- **M√©todo creado:** `process_invoice_upload_patterns(user_id: str, filename: str, processing_result: Dict[str, Any])`
- **Verificaci√≥n de sintaxis:** ‚úÖ Sin errores (`py_compile` exitoso)
- **Integraci√≥n:** ‚úÖ Utiliza m√©todos existentes (`process_enterprise_interaction`)

**C√ìDIGO DE LA SOLUCI√ìN:**

```python
def process_invoice_upload_patterns(
    self, user_id: str, filename: str, processing_result: Dict[str, Any]
) -> Dict[str, Any]:
    """üè¢ Procesar patrones de carga de facturas empresariales"""
    try:
        # Crear datos de aprendizaje espec√≠ficos para facturas
        learning_data = {
            "user_id": user_id,
            "interaction_type": "invoice_upload",
            "filename": filename,
            "processing_result": processing_result,
            # ... m√°s datos de contexto
        }
        # Usar el m√©todo de procesamiento empresarial existente
        result = self.process_enterprise_interaction(learning_data)
        return result
    except Exception as e:
        logging.error(f"Error procesando patrones de factura para {user_id}: {e}")
        return {"status": "error", "error": str(e)}
```

- **An√°lisis y Causa Ra√≠z:**
  - **CONFIRMADO:** AttributeError por m√©todo faltante en `AILearningService`
  - **SOLUCIONADO:** M√©todo implementado con par√°metros exactos requeridos por `energy_routes.py`
  - **COMPATIBILIDAD:** No afecta otros m√©todos existentes, utiliza infraestructura empresarial disponible
- **Impacto:** Cr√≠tico ‚Üí **RESUELTO**. El endpoint ahora puede ejecutarse completamente sin errores.

- **Flujo verificado:** `user_id` (str) + `file.filename` (str) + `result` (Dict[str, Any]) ‚Üí Procesamiento exitoso

### Error 1.2: Fallo de Permisos para Publicar en Pub/Sub ‚úÖ VERIFICADO

- **Timestamp (UTC):** ~2025-08-05T15:07:58Z - 15:08:01Z (17:08 Hora Local)
- **Endpoint Afectado:** `POST /api/v1/energy/consumption`
- **Mensaje de Error Clave:** `Error publicando a Pub/Sub: 403 User not authorized to perform this action.`

**VERIFICACI√ìN DEL C√ìDIGO CONFIRMADA:**

- **Archivo:** `expert_bot_api_COPY/app/services/energy_service.py`
- **M√©todo:** `_publish_with_retries()` (l√≠neas 1368-1381)
- **Ubicaci√≥n espec√≠fica:** Llamadas a `publisher.publish()` que generan 403

**C√ìDIGO VERIFICADO QUE GENERA EL ERROR:**

```python
# L√≠neas 1368-1381: M√©todo que intenta publicar a Pub/Sub
def _publish_with_retries(self, topic, message_data, retries=3):
    for attempt in range(retries):
        try:
            future = self.publisher.publish(topic, message_data.encode('utf-8'))
            return future.result(timeout=10)
        except Exception as e:
            if attempt == retries - 1:
                logging.error(f"Error publicando a Pub/Sub despu√©s de {retries} intentos: {e}")
                raise
```

- **An√°lisis y Causa Ra√≠z:**
  - **CONFIRMADO:** Error de configuraci√≥n de infraestructura en Google Cloud. La cuenta de servicio asociada al servicio de Cloud Run `expert-bot-api` no tiene los permisos de IAM necesarios para publicar mensajes en el tema de Pub/Sub.
  - **PROBLEMA ESPEC√çFICO:** El error `403 Forbidden` indica expl√≠citamente una denegaci√≥n de permiso persistente tras m√∫ltiples reintentos.
- **Impacto:** Alto. El sistema no puede notificar a otros servicios o registrar eventos a trav√©s de Pub/Sub, lo que puede romper flujos de trabajo as√≠ncronos.

- **Soluci√≥n Recomendada:** Asignar el rol `roles/pubsub.publisher` a la cuenta de servicio de `expert-bot-api` en el proyecto `smatwatt` usando Google Cloud IAM.

### Error 1.3: Error de Tipo de Dato al Escribir en BigQuery ‚úÖ VERIFICADO

- **Timestamp (UTC):** 2025-08-05T15:07:58.063608Z (17:07 Hora Local)
- **Endpoint Afectado:** `POST /api/v1/energy/consumption` (inferido por el flujo de logs)
- **Usuario afectado:** testing_production_user_2025
- **Mensaje de Error Clave:** `Error insertando/actualizando perfil en BigQuery ... Invalid value for type: BOOLEAN is not a valid value`

**VERIFICACI√ìN DEL C√ìDIGO CONFIRMADA:**

- **Archivo:** `expert_bot_api_COPY/app/services/energy_service.py`
- **M√©todo:** `_insert_or_update_user_profile_in_bigquery()` (l√≠neas 1610-1784)
- **Ubicaci√≥n espec√≠fica:** L√≠neas 1737-1745 (inserci√≥n de par√°metros BOOLEAN)

**C√ìDIGO VERIFICADO:**

```python
# L√≠neas 1633-1640: Preparaci√≥n de datos BOOLEAN
"has_ac": profile_data.get("has_ac", False),
"has_pool": profile_data.get("has_pool", False),
"is_teleworker": profile_data.get("is_teleworker", False),
"has_solar_panels": profile_data.get("has_solar_panels", False),

# L√≠neas 1737-1745: Inserci√≥n a BigQuery con par√°metros BOOLEAN
bigquery.ScalarQueryParameter("has_ac", "BOOLEAN", row_data["has_ac"]),
bigquery.ScalarQueryParameter("has_pool", "BOOLEAN", row_data["has_pool"]),
bigquery.ScalarQueryParameter("is_teleworker", "BOOLEAN", row_data["is_teleworker"]),
```

- **An√°lisis y Causa Ra√≠z:**
  - **CONFIRMADO:** Los campos BOOLEAN en `profile_data` pueden contener valores no booleanos (strings, n√∫meros, null) que no se validan antes de la inserci√≥n. El m√©todo `.get()` con valor por defecto `False` no garantiza que el valor original sea un booleano v√°lido.
  - **PROBLEMA IDENTIFICADO:** Si `profile_data` contiene valores como `"true"`, `"false"`, `1`, `0`, o `None` para estos campos, BigQuery rechaza la inserci√≥n porque espera estrictamente valores booleanos de Python (`True`/`False`).
- **Impacto:** Alto. Impide que los datos de perfil de usuario se guarden o actualicen correctamente en BigQuery, afectando la anal√≠tica y la persistencia de datos empresariales.

- **Soluci√≥n Recomendada:** Implementar validaci√≥n expl√≠cita de tipos antes de la inserci√≥n:

```python
# Funci√≥n helper para convertir a boolean seguro
def safe_bool(value, default=False):
    if isinstance(value, bool):
        return value
    if isinstance(value, str):
        return value.lower() in ('true', '1', 'yes', 'on')
    if isinstance(value, int):
        return bool(value)
    return default

# Aplicar en la preparaci√≥n de datos
"has_ac": safe_bool(profile_data.get("has_ac"), False),
"has_pool": safe_bool(profile_data.get("has_pool"), False),
```
